Workbook

Sheet Web_of_Science_20251015 
A1: title | B1: DOI | C1: display_names | D1: OA_URLs | E1: Number of Funders Indicated by Paper | F1: Number of Correct Matches | G1: Number of Wrong Matches | H1: Coder | I1: Avg. Recall | J1: Avg error rate | K1: Hit rate | L1: Avg. Precision | M1: Paper level recall | N1: Paper level error rate | O1: Paper level hit rate | P1: Paper level precision | Q1: Paper is complete hit
A2: Integral-Type Fractional Equations with a Proportional Riemann-Liouville Derivative | B2: https://doi.org/10.1155/2021/9990439 | C2: Prince Sultan University; PSU | D2: https://openalex.org/funders/f4320327702 | E2: =sample_20250925!E2 -> 1 | F2: =IF(sample_20250925!$C2=C2,sample_20250925!F2, NA()) -> 1 | G2: =IF(sample_20250925!$C2=$C2,sample_20250925!G2, NA()) -> 0 | H2: Jacob | I2: =IFERROR(__xludf.DUMMYFUNCTION("AVERAGE(FILTER(M2:M250,ISNUMBER(M2:M250)))"),0.7796877568754548) -> 0.77968776 | J2: =IFERROR(__xludf.DUMMYFUNCTION("AVERAGE(FILTER(N2:N250,ISNUMBER(N2:N250)))"),0.03572485430443579) -> 0.035724854 | K2: =IFERROR(__xludf.DUMMYFUNCTION("AVERAGE(FILTER(O2:O250,ISNUMBER(O2:O250)))"),0.9799196787148594) -> 0.97991968 | L2: =IFERROR(__xludf.DUMMYFUNCTION("AVERAGE(FILTER(P2:P250,ISNUMBER(P2:P250)))"),0.9626349527665317) -> 0.96263495 | M2: =F2/E2 -> 1 | N2: =G2/E2 -> 0 | O2: =IFERROR(__xludf.DUMMYFUNCTION("INT(FILTER(GT(F2,0),ISNUMBER(F2)))"),1.0) -> 1 | P2: =F2/(F2+G2) -> 1 | Q2: =IFERROR(__xludf.DUMMYFUNCTION("INT(FILTER(EQ(E2,F2),ISNUMBER(E2),ISNUMBER(F2)))"),1.0) -> 1
A3: Meta-analysis of day treatment and contingency-management dismantling research: Birmingham homeless cocaine studies (1990-2006) | B3: https://doi.org/10.1037/0022-006X.75.5.823 | C3: National Institute on Alcohol Abuse and Alcoholism; NIH National Institute on Alcohol Abuse and Alcoholism; The National Institute on Alcohol Abuse and Alcoholism; NIAAA; National Institute on Alcohol Abuse & Alcoholism || National Institute on Drug Abuse; NIDA; The National Institute on Drug Abuse; Instituto Nacional sobre el Abuso de Drogas; Instituto Nacional sobre el Abuso de Drogas de Estados Unidos || National Institute on Alcohol Abuse and Alcoholism; NIH National Institute on Alcohol Abuse and Alcoholism; The National Institute on Alcohol Abuse and Alcoholism; NIAAA; National Institute on Alcohol Abuse & Alcoholism || National Institute on Drug Abuse; NIDA; The National Institute on Drug Abuse; Instituto Nacional sobre el Abuso de Drogas; Instituto Nacional sobre el Abuso de Drogas de Estados Unidos | D3: https://openalex.org/funders/f4320337347 || https://openalex.org/funders/f4320337330 | E3: =sample_20250925!E3 -> 1 | F3: =IF(sample_20250925!$C3=C3,sample_20250925!F3, NA()) -> 1 | G3: =IF(sample_20250925!$C3=$C3,sample_20250925!G3, NA()) -> 0 | H3: Jacob | I3: Recall | J3: Error rate | K3: Complete hits | L3: Precision | M3: =F3/E3 -> 1 | N3: =G3/E3 -> 0 | O3: =IFERROR(__xludf.DUMMYFUNCTION("INT(FILTER(GT(F3,0),ISNUMBER(F3)))"),1.0) -> 1 | P3: =F3/(F3+G3) -> 1 | Q3: =IFERROR(__xludf.DUMMYFUNCTION("INT(FILTER(EQ(E3,F3),ISNUMBER(E3),ISNUMBER(F3)))"),1.0) -> 1
A4: MR Imaging-guided Percutaneous Cryoablation of the Prostate in an Animal Model: In Vivo Imaging of Cryoablation-induced Tissue Necrosis with Immediate Histopathologic Correlation | B4: https://doi.org/10.1016/j.jvir.2008.10.030 | C4: National Center for Research Resources; NCRR || National Cancer Institute; NCI; Instituto Nacional del Cáncer || National Center for Research Resources; NCRR | D4: https://openalex.org/funders/f4320337351 || https://openalex.org/funders/f4320337375 | E4: =sample_20250925!E4 -> 2 | F4: =IF(sample_20250925!$C4=C4,sample_20250925!F4, NA()) -> 2 | G4: =IF(sample_20250925!$C4=$C4,sample_20250925!G4, NA()) -> 0 | H4: Jacob | I4: =IFERROR(__xludf.DUMMYFUNCTION("SUM(FILTER(F2:F250,ISNUMBER(F2:F250)))/SUM(FILTER(E2:E250,ISNUMBER(F2:F250)))"),0.7300613496932515) -> 0.73006135 | J4: =IFERROR(__xludf.DUMMYFUNCTION("SUM(FILTER(G2:G250,ISNUMBER(G2:G250)))/SUM(FILTER(E2:E250,ISNUMBER(G2:G250)))"),0.029141104294478526) -> 0.029141104 | K4: =IFERROR(__xludf.DUMMYFUNCTION("AVERAGE(FILTER(Q2:Q250,ISNUMBER(Q2:Q250)))"),0.5418502202643172) -> 0.54185022 | L4: =IFERROR(__xludf.DUMMYFUNCTION("SUM(FILTER(F2:F250,ISNUMBER(F2:F250)))/(SUM(FILTER(F2:F250,ISNUMBER(F2:F250)))+SUM(FILTER(G2:G250,ISNUMBER(F2:F250))))"),0.9616161616161616) -> 0.96161616 | M4: =F4/E4 -> 1 | N4: =G4/E4 -> 0 | O4: =IFERROR(__xludf.DUMMYFUNCTION("INT(FILTER(GT(F4,0),ISNUMBER(F4)))"),1.0) -> 1 | P4: =F4/(F4+G4) -> 1 | Q4: =IFERROR(__xludf.DUMMYFUNCTION("INT(FILTER(EQ(E4,F4),ISNUMBER(E4),ISNUMBER(F4)))"),1.0) -> 1
A5: Enzymatic Hydrolysis of Softwood Derived Paper Sludge by an In Vitro Recombinant Cellulase Cocktail for the Production of Fermentable Sugars | B5: https://doi.org/10.3390/catal10070775 | C5: Department of Science and Technology, Republic of South Africa; DST || National Research Foundation; NRF || Rhodes University; RU; ru.ac.za; Rhodes University College || Universiteit Stellenbosch; Stellenbosch University; US | D5: https://openalex.org/funders/f4320320671 || https://openalex.org/funders/f4320322663 || https://openalex.org/funders/f4320320691 || https://openalex.org/funders/f4320320683 | E5: =sample_20250925!E5 -> 4 | F5: 4 | G5: 0 | H5: Jacob | M5: =F5/E5 -> 1 | N5: =G5/E5 -> 0 | O5: =IFERROR(__xludf.DUMMYFUNCTION("INT(FILTER(GT(F5,0),ISNUMBER(F5)))"),1.0) -> 1 | P5: =F5/(F5+G5) -> 1 | Q5: =IFERROR(__xludf.DUMMYFUNCTION("INT(FILTER(EQ(E5,F5),ISNUMBER(E5),ISNUMBER(F5)))"),1.0) -> 1
A6: Metal nanoparticle-doped epoxy resin to suppress surface charge accumulation on insulators under DC voltage | B6: https://doi.org/10.1088/1361-6528/ab8b91 | C6: National Key Research and Development Program of China; NKRDPC; Special Fund for the National Key Research and Development Plan; 973 Program; National Basic Research Program of China; NKPs; National Plan on Key Basic Research and Development; National Program on Key Basic Research Project (973 Program); National Key Research and Development of China; 重点基础研究发展计划; National Key R&D Program of China; National Key R&D Programmes of China; China's National Key R&D Programmes; National Basic Research Program; National Basic Research Program of China (973 Program); China National Key Research and Development Plan Project; National Key Research and Development Program | D6: https://openalex.org/funders/f4320335777 | E6: =sample_20250925!E6 -> 1 | F6: =IF(sample_20250925!$C6=C6,sample_20250925!F6, NA()) -> 1 | G6: =IF(sample_20250925!$C6=$C6,sample_20250925!G6, NA()) -> 0 | H6: Jacob | M6: =F6/E6 -> 1 | N6: =G6/E6 -> 0 | O6: =IFERROR(__xludf.DUMMYFUNCTION("INT(FILTER(GT(F6,0),ISNUMBER(F6)))"),1.0) -> 1 | P6: =F6/(F6+G6) -> 1 | Q6: =IFERROR(__xludf.DUMMYFUNCTION("INT(FILTER(EQ(E6,F6),ISNUMBER(E6),ISNUMBER(F6)))"),1.0) -> 1
A7: IJCARS-IPCAI 2021 Special Issue: Information Processing for Computer-Assisted Interventions, 12th International Conference 2021-Part 1 | B7: https://doi.org/10.1007/s11548-021-02401-5 | C7: German Rectors' Conference; HRK; Westdeutsche Rektorenkonferenz; Hochschulrektorenkonferenz | D7: https://openalex.org/institutions/i4210095069 | E7: =sample_20250925!E7 -> 1 | F7: =IF(sample_20250925!$C7=C7,sample_20250925!F7, NA()) -> 1 | G7: =IF(sample_20250925!$C7=$C7,sample_20250925!G7, NA()) -> 0 | H7: Jacob | M7: =F7/E7 -> 1 | N7: =G7/E7 -> 0 | O7: =IFERROR(__xludf.DUMMYFUNCTION("INT(FILTER(GT(F7,0),ISNUMBER(F7)))"),1.0) -> 1 | P7: =F7/(F7+G7) -> 1 | Q7: =IFERROR(__xludf.DUMMYFUNCTION("INT(FILTER(EQ(E7,F7),ISNUMBER(E7),ISNUMBER(F7)))"),1.0) -> 1
A8: Identification and partial characterization of a Salp15 homolog from Ixodes ricinus | B8: https://doi.org/10.1016/j.ttbdis.2013.12.004 | C8: European Commission; Europeiska kommissionen; Ευρωπαϊκής Επιτροπής; Comisia Europeană; Europese Commissie; Euroopa Komisjoni; Eiropas Komisiju; Euroopan komission; Europskoj komisiji; EU; Choimisiúin Eorpaigh; EU-Kommissionen; Evropski komisiji; EC; Comisión Europea; Europos Komisijos; Europäische Kommission; La Commissione europea; Evropské komise; Comissão Europeia; Európskej komisii; Европейската комисия; Európai Bizottságról; Komisja Europejska; Commissione europea; European Union; Commission européenne | D8: https://openalex.org/funders/f4320320300 | E8: =sample_20250925!E8 -> 1 | F8: 1 | G8: 0 | H8: Jacob | M8: =F8/E8 -> 1 | N8: =G8/E8 -> 0 | O8: =IFERROR(__xludf.DUMMYFUNCTION("INT(FILTER(GT(F8,0),ISNUMBER(F8)))"),1.0) -> 1 | P8: =F8/(F8+G8) -> 1 | Q8: =IFERROR(__xludf.DUMMYFUNCTION("INT(FILTER(EQ(E8,F8),ISNUMBER(E8),ISNUMBER(F8)))"),1.0) -> 1
A9: Discovery of platelet-type 12-human lipoxygenase selective inhibitors by high-throughput screening of structurally diverse libraries | B9: https://doi.org/10.1016/j.bmc.2007.08.015 | C9: National Cancer Institute; NCI; Instituto Nacional del Cáncer || National Institute of General Medical Sciences; NIGMS; U.S. National Institute of General Medical Sciences || National Cancer Institute; NCI; Instituto Nacional del Cáncer || National Institute of General Medical Sciences; NIGMS; U.S. National Institute of General Medical Sciences | D9: https://openalex.org/funders/f4320337351 || https://openalex.org/funders/f4320337354 | E9: =sample_20250925!E9 -> 3 | F9: =IF(sample_20250925!$C9=C9,sample_20250925!F9, NA()) -> 2 | G9: =IF(sample_20250925!$C9=$C9,sample_20250925!G9, NA()) -> 0 | H9: Jacob | M9: =F9/E9 -> 0.66666667 | N9: =G9/E9 -> 0 | O9: =IFERROR(__xludf.DUMMYFUNCTION("INT(FILTER(GT(F9,0),ISNUMBER(F9)))"),1.0) -> 1 | P9: =F9/(F9+G9) -> 1 | Q9: =IFERROR(__xludf.DUMMYFUNCTION("INT(FILTER(EQ(E9,F9),ISNUMBER(E9),ISNUMBER(F9)))"),0.0) -> 0
A10: Constructing mentally ill inmates: nurses' discursive practices in corrections | B10: https://doi.org/10.1111/j.1440-1800.2011.00526.x | C10: Canadian Institutes of Health Research; CIHR; IRSC; Instituts de Recherche en Santé du Canada | D10: https://openalex.org/funders/f4320334506 | E10: =sample_20250925!E10 -> 1 | F10: =IF(sample_20250925!$C10=C10,sample_20250925!F10, NA()) -> 1 | G10: =IF(sample_20250925!$C10=$C10,sample_20250925!G10, NA()) -> 0 | H10: Jacob | M10: =F10/E10 -> 1 | N10: =G10/E10 -> 0 | O10: =IFERROR(__xludf.DUMMYFUNCTION("INT(FILTER(GT(F10,0),ISNUMBER(F10)))"),1.0) -> 1 | P10: =F10/(F10+G10) -> 1 | Q10: =IFERROR(__xludf.DUMMYFUNCTION("INT(FILTER(EQ(E10,F10),ISNUMBER(E10),ISNUMBER(F10)))"),1.0) -> 1
A11: An in vivo study on bone formation behavior of microporous granular calcium phosphate | B11: https://doi.org/10.1039/c7bm00162b | C11: Coordenação de Aperfeiçoamento de Pessoal de Nível Superior; Coordination for the Improvement of Higher Education Personnel; CAPES; Brazilian Federal Agency for the Support and Evaluation of Graduate Education || Ministerio de Economía y Competitividad; MINECO; MEC; Ministry of Economy and Competitiveness | D11: https://openalex.org/funders/f4320321091 || https://openalex.org/funders/f4320321837 | E11: =sample_20250925!E11 -> 2 | F11: =IF(sample_20250925!$C11=C11,sample_20250925!F11, NA()) -> 2 | G11: =IF(sample_20250925!$C11=$C11,sample_20250925!G11, NA()) -> 0 | H11: Jacob | M11: =F11/E11 -> 1 | N11: =G11/E11 -> 0 | O11: =IFERROR(__xludf.DUMMYFUNCTION("INT(FILTER(GT(F11,0),ISNUMBER(F11)))"),1.0) -> 1 | P11: =F11/(F11+G11) -> 1
A12: Self-directedly assembled porphyrin thin films with high photoactivity | B12: https://doi.org/10.1039/c5ra17015j | C12: National Natural Science Foundation of China; NNSF of China; Guójiā Zìrán Kēxué Jījīn Wěiyuánhuì; NSF of China; The National Natural Science Foundation of China; 国家自然科学基金委员会; National Nature Science Foundation of China; NSFC; National Science Foundation of China; Natural Science Foundation of China; NNSFC; Chinese National Science Foundation; NNSF || Shanghai Municipal Education Commission; Education Commission of Shanghai Municipality; 上海市教育委员会 | D12: https://openalex.org/funders/f4320321881 || https://openalex.org/funders/f4320321001 | E12: =sample_20250925!E12 -> 2 | F12: =IF(sample_20250925!$C12=C12,sample_20250925!F12, NA()) -> 2 | G12: =IF(sample_20250925!$C12=$C12,sample_20250925!G12, NA()) -> 0 | H12: Jacob | M12: =F12/E12 -> 1 | N12: =G12/E12 -> 0 | O12: =IFERROR(__xludf.DUMMYFUNCTION("INT(FILTER(GT(F12,0),ISNUMBER(F12)))"),1.0) -> 1 | P12: =F12/(F12+G12) -> 1 | Q12: =IFERROR(__xludf.DUMMYFUNCTION("INT(FILTER(EQ(E12,F12),ISNUMBER(E12),ISNUMBER(F12)))"),1.0) -> 1
A13: Human Schlafen 5 (SLFN5) Is a Regulator of Motility and Invasiveness of Renal Cell Carcinoma Cells | B13: https://doi.org/10.1128/MCB.00019-15 | C13: National Institutes of Health; US National Institutes of Health; Institutos Nacionales de la Salud; NIH || U.S. Department of Veterans Affairs; United States Department of Veterans Affairs; Veterans Affairs; Veterans Affairs Department; Department of Veterans Affairs; US Department of Veterans Affairs; VA; U.S. Dept. of Veterans Affairs; USDVA || National Cancer Institute; NCI; Instituto Nacional del Cáncer || National Center for Advancing Translational Sciences; NCATS; NIH-NCATS; NIH's National Center for Advancing Translational; NCATS NIH || U.S. Department of Veterans Affairs; United States Department of Veterans Affairs; Veterans Affairs; Veterans Affairs Department; Department of Veterans Affairs; US Department of Veterans Affairs; VA; U.S. Dept. of Veterans Affairs; USDVA | D13: https://openalex.org/funders/f4320332161 || https://openalex.org/funders/f4320337351 || https://openalex.org/funders/f4320306127 || https://openalex.org/funders/f4320337472 | E13: 3 | F13: 3 | G13: 0 | H13: Jacob | M13: =F13/E13 -> 1 | N13: =G13/E13 -> 0 | O13: =IFERROR(__xludf.DUMMYFUNCTION("INT(FILTER(GT(F13,0),ISNUMBER(F13)))"),1.0) -> 1 | P13: =F13/(F13+G13) -> 1 | Q13: =IFERROR(__xludf.DUMMYFUNCTION("INT(FILTER(EQ(E13,F13),ISNUMBER(E13),ISNUMBER(F13)))"),1.0) -> 1
A14: STRUCTURAL ELUCIDATION OF A NEUTRAL WATER-SOLUBLE a-D-GLUCAN FROM THE FUNGUS OF HERICIUM ERINACEUS | B14: https://doi.org/10.1111/j.1745-4514.2010.00492.x | C14: NOT MATCHED || Natural Science Foundation of Zhejiang Province; Zhejiang Natural Science Foundation; ZJNSF; 浙江省自然科学基金根据国; Zhejiang Provincial Natural Science Foundation | D14: https://openalex.org/funders/f4320338464 | E14: =sample_20250925!E14 -> 2 | F14: 1 | G14: 0 | H14: Jacob | M14: =F14/E14 -> 0.5 | N14: =G14/E14 -> 0 | O14: =IFERROR(__xludf.DUMMYFUNCTION("INT(FILTER(GT(F14,0),ISNUMBER(F14)))"),1.0) -> 1 | P14: =F14/(F14+G14) -> 1 | Q14: =IFERROR(__xludf.DUMMYFUNCTION("INT(FILTER(EQ(E14,F14),ISNUMBER(E14),ISNUMBER(F14)))"),0.0) -> 0
A15: Localization of Free and Bound Metal Species through X-Ray Synchrotron Fluorescence Microscopy in the Rodent Brain and Their Relation to Behavior | B15: https://doi.org/10.3390/brainsci9040074 | C15: U.S. Department of Energy; US Department of Energy; DOE; United States Department of Energy; Department of Energy; USDOE; Energy Department; ENERGY.GOV; USADOE; US DOE || U.S. Department of Energy; US Department of Energy; DOE; United States Department of Energy; Department of Energy; USDOE; Energy Department; ENERGY.GOV; USADOE; US DOE | D15: https://openalex.org/funders/f4320306084 | E15: =sample_20250925!E15 -> 1 | F15: =IF(sample_20250925!$C15=C15,sample_20250925!F15, NA()) -> 1 | G15: =IF(sample_20250925!$C15=$C15,sample_20250925!G15, NA()) -> 0 | H15: Jacob | M15: =F15/E15 -> 1 | N15: =G15/E15 -> 0 | O15: =IFERROR(__xludf.DUMMYFUNCTION("INT(FILTER(GT(F15,0),ISNUMBER(F15)))"),1.0) -> 1 | P15: =F15/(F15+G15) -> 1 | Q15: =IFERROR(__xludf.DUMMYFUNCTION("INT(FILTER(EQ(E15,F15),ISNUMBER(E15),ISNUMBER(F15)))"),1.0) -> 1
A16: Establishment, Persistence, and Reactivation of Latent HIV-1 Infection in Renal Epithelial Cells | B16: https://doi.org/10.1128/jvi.00624-22 | C16: National Institute of Diabetes and Digestive and Kidney Diseases; NIH\/National Institute of Diabetes, Digestive & Kidney Diseases; NIH National Institute of Diabetes and Digestive and Kidney Diseases; NIDDK; National Institute of Diabetes & Digestive & Kidney Diseases | D16: https://openalex.org/funders/f4320337357 | E16: =sample_20250925!E16 -> 1 | F16: =IF(sample_20250925!$C16=C16,sample_20250925!F16, NA()) -> 1 | G16: =IF(sample_20250925!$C16=$C16,sample_20250925!G16, NA()) -> 0 | H16: Jacob | M16: =F16/E16 -> 1 | N16: =G16/E16 -> 0 | O16: =IFERROR(__xludf.DUMMYFUNCTION("INT(FILTER(GT(F16,0),ISNUMBER(F16)))"),1.0) -> 1 | P16: =F16/(F16+G16) -> 1 | Q16: =IFERROR(__xludf.DUMMYFUNCTION("INT(FILTER(EQ(E16,F16),ISNUMBER(E16),ISNUMBER(F16)))"),1.0) -> 1
A17: Parallel ddRAD and Genome Skimming Analyses Reveal a Radiative and Reticulate Evolutionary History of the Temperate Bamboos | B17: https://doi.org/10.1093/sysbio/syaa076 | C17: Chinese Academy of Sciences; CAS; 中国科学院 || National Natural Science Foundation of China; NNSF of China; Guójiā Zìrán Kēxué Jījīn Wěiyuánhuì; NSF of China; The National Natural Science Foundation of China; 国家自然科学基金委员会; National Nature Science Foundation of China; NSFC; National Science Foundation of China; Natural Science Foundation of China; NNSFC; Chinese National Science Foundation; NNSF || NOT MATCHED || University of Chinese Academy of Sciences; 中国科学院大学; University of the Chinese Academy of Sciences; UCAS; Graduate University of Chinese Academy of Sciences | D17: https://openalex.org/funders/f4320321133 || https://openalex.org/funders/f4320326972 || https://openalex.org/funders/f4320321001 | E17: =sample_20250925!E17 -> 4 | F17: 3 | G17: 0 | H17: Jacob | M17: =F17/E17 -> 0.75 | N17: =G17/E17 -> 0 | O17: =IFERROR(__xludf.DUMMYFUNCTION("INT(FILTER(GT(F17,0),ISNUMBER(F17)))"),1.0) -> 1 | P17: =F17/(F17+G17) -> 1 | Q17: =IFERROR(__xludf.DUMMYFUNCTION("INT(FILTER(EQ(E17,F17),ISNUMBER(E17),ISNUMBER(F17)))"),0.0) -> 0
A18: Casting a Black Gandhi: Martin Luther King Jr., American Pacifists and the Global Dynamics of Race | B18: https://doi.org/10.1017/S0021875819000033 | C18: Arts and Humanities Research Council; AHRC || Economic and Social Research Council; ESRC || Arts and Humanities Research Council; AHRC | D18: https://openalex.org/funders/f4320334609 || https://openalex.org/funders/f4320334630 | E18: =sample_20250925!E18 -> 2 | F18: =IF(sample_20250925!$C18=C18,sample_20250925!F18, NA()) -> 2 | G18: =IF(sample_20250925!$C18=$C18,sample_20250925!G18, NA()) -> 0 | H18: Jacob | M18: =F18/E18 -> 1 | N18: =G18/E18 -> 0 | O18: =IFERROR(__xludf.DUMMYFUNCTION("INT(FILTER(GT(F18,0),ISNUMBER(F18)))"),1.0) -> 1 | P18: =F18/(F18+G18) -> 1 | Q18: =IFERROR(__xludf.DUMMYFUNCTION("INT(FILTER(EQ(E18,F18),ISNUMBER(E18),ISNUMBER(F18)))"),1.0) -> 1
A19: Synthesis of 2-Vinylbenzofurans via the Copper-Catalyzed Multicomponent Reactions Involving an Oxa-Michael/Arylation/Vinylation Cascade | B19: https://doi.org/10.1021/ol502506g | C19: National Natural Science Foundation of China; NNSF of China; Guójiā Zìrán Kēxué Jījīn Wěiyuánhuì; NSF of China; The National Natural Science Foundation of China; 国家自然科学基金委员会; National Nature Science Foundation of China; NSFC; National Science Foundation of China; Natural Science Foundation of China; NNSFC; Chinese National Science Foundation; NNSF || Education Department of Jiangxi Province; Department of Education, Jiangxi Province; Jiangxi Provincial Education Department; 江西省教育厅; Department of Education of Jiangxi Province; Jiangxi Provincial Department of Education | D19: https://openalex.org/funders/f4320325626 || https://openalex.org/funders/f4320321001 | E19: =sample_20250925!E19 -> 2 | F19: =IF(sample_20250925!$C19=C19,sample_20250925!F19, NA()) -> 2 | G19: =IF(sample_20250925!$C19=$C19,sample_20250925!G19, NA()) -> 0 | H19: Jacob | M19: =F19/E19 -> 1 | N19: =G19/E19 -> 0 | O19: =IFERROR(__xludf.DUMMYFUNCTION("INT(FILTER(GT(F19,0),ISNUMBER(F19)))"),1.0) -> 1 | P19: =F19/(F19+G19) -> 1 | Q19: =IFERROR(__xludf.DUMMYFUNCTION("INT(FILTER(EQ(E19,F19),ISNUMBER(E19),ISNUMBER(F19)))"),1.0) -> 1
A20: A thermosensitive molecularly imprinted poly-NIPAM coated MWCNTs/TiO2 photocatalyst for the preferential removal of pendimethalin pesticide from wastewater | B20: https://doi.org/10.1016/j.jphotochem.2020.112802 | C20: Shahid Beheshti University; دانشگاه شهید بهشتی; SBU | D20: https://openalex.org/funders/f4320319808 | E20: =sample_20250925!E20 -> 1 | F20: =IF(sample_20250925!$C20=C20,sample_20250925!F20, NA()) -> 1 | G20: =IF(sample_20250925!$C20=$C20,sample_20250925!G20, NA()) -> 0 | H20: Jacob | M20: =F20/E20 -> 1 | N20: =G20/E20 -> 0 | O20: =IFERROR(__xludf.DUMMYFUNCTION("INT(FILTER(GT(F20,0),ISNUMBER(F20)))"),1.0) -> 1 | P20: =F20/(F20+G20) -> 1 | Q20: =IFERROR(__xludf.DUMMYFUNCTION("INT(FILTER(EQ(E20,F20),ISNUMBER(E20),ISNUMBER(F20)))"),1.0) -> 1
A21: Renal Cell Carcinoma in the Era of Precision Medicine: From Molecular Pathology to Tissue-Based Biomarkers | B21: https://doi.org/10.1200/JCO.2018.79.2259 | C21: National Institutes of Health; US National Institutes of Health; Institutos Nacionales de la Salud; NIH || Memorial Sloan-Kettering Cancer Center; MSK Cancer Center; Memorial Sloan Kettering Cancer Center; MSKCC; MSK; Memorial Sloan Kettering || Society of Memorial Sloan Kettering; Society of MSK || National Cancer Institute; NCI; Instituto Nacional del Cáncer | D21: https://openalex.org/funders/f4320332161 || https://openalex.org/funders/f4320309468 || https://openalex.org/funders/f4320313397 || https://openalex.org/funders/f4320337351 | E21: =sample_20250925!E21 -> 5 | F21: =IF(sample_20250925!$C21=C21,sample_20250925!F21, NA()) -> 4 | G21: =IF(sample_20250925!$C21=$C21,sample_20250925!G21, NA()) -> 0 | H21: Jacob | M21: =F21/E21 -> 0.8 | N21: =G21/E21 -> 0 | O21: =IFERROR(__xludf.DUMMYFUNCTION("INT(FILTER(GT(F21,0),ISNUMBER(F21)))"),1.0) -> 1 | P21: =F21/(F21+G21) -> 1 | Q21: =IFERROR(__xludf.DUMMYFUNCTION("INT(FILTER(EQ(E21,F21),ISNUMBER(E21),ISNUMBER(F21)))"),0.0) -> 0
A22: CAIR-1/BAG-3 modulates cell adhesion and migration by downregulating activity of focal adhesion proteins | B22: https://doi.org/10.1016/j.yexcr.2006.05.023 | C22: National Cancer Institute; NCI; Instituto Nacional del Cáncer || National Institutes of Health; US National Institutes of Health; Institutos Nacionales de la Salud; NIH | D22: https://openalex.org/funders/f4320332161 || https://openalex.org/funders/f4320337351 | E22: =sample_20250925!E22 -> 2 | F22: =IF(sample_20250925!$C22=C22,sample_20250925!F22, NA()) -> 2 | G22: =IF(sample_20250925!$C22=$C22,sample_20250925!G22, NA()) -> 0 | H22: Jacob | M22: =F22/E22 -> 1 | N22: =G22/E22 -> 0 | O22: =IFERROR(__xludf.DUMMYFUNCTION("INT(FILTER(GT(F22,0),ISNUMBER(F22)))"),1.0) -> 1 | P22: =F22/(F22+G22) -> 1
A23: Non-Markovian Exciton-Phonon Interactions in Core-Shell Colloidal Quantum Dots at Femtosecond Timescales | B23: https://doi.org/10.1103/PhysRevLett.123.057403 | C23: U.S. Department of Energy; US Department of Energy; DOE; United States Department of Energy; Department of Energy; USDOE; Energy Department; ENERGY.GOV; USADOE; US DOE || Conselho Nacional de Desenvolvimento Científico e Tecnológico; National Council for Scientific and Technological Development; Brazilian National Council for Research and Development; CNPq || Fundação de Amparo à Pesquisa do Estado de São Paulo; São Paulo Research Foundation; Foundation for Research Support of the State of São Paulo; FAPESP; State of São Paulo Research Foundation | D23: https://openalex.org/funders/f4320306084 || https://openalex.org/funders/f4320322025 || https://openalex.org/funders/f4320320997 | E23: =sample_20250925!E23 -> 3 | F23: =IF(sample_20250925!$C23=C23,sample_20250925!F23, NA()) -> 3 | G23: =IF(sample_20250925!$C23=$C23,sample_20250925!G23, NA()) -> 0 | H23: Jacob | M23: =F23/E23 -> 1 | N23: =G23/E23 -> 0 | O23: =IFERROR(__xludf.DUMMYFUNCTION("INT(FILTER(GT(F23,0),ISNUMBER(F23)))"),1.0) -> 1 | P23: =F23/(F23+G23) -> 1 | Q23: =IFERROR(__xludf.DUMMYFUNCTION("INT(FILTER(EQ(E23,F23),ISNUMBER(E23),ISNUMBER(F23)))"),1.0) -> 1
A24: Nrf2 augments skeletal muscle regeneration after ischaemia-reperfusion injury | B24: https://doi.org/10.1002/path.4418 | C24: NOT MATCHED || NOT MATCHED || Deutsche Forschungsgemeinschaft; German Research Association; DFG; German Research Foundation | D24: https://openalex.org/funders/f4320320879 | E24: =sample_20250925!E24 -> 3 | F24: 1 | G24: 0 | H24: Jacob | M24: =F24/E24 -> 0.33333333 | N24: =G24/E24 -> 0 | O24: =IFERROR(__xludf.DUMMYFUNCTION("INT(FILTER(GT(F24,0),ISNUMBER(F24)))"),1.0) -> 1 | P24: =F24/(F24+G24) -> 1 | Q24: =IFERROR(__xludf.DUMMYFUNCTION("INT(FILTER(EQ(E24,F24),ISNUMBER(E24),ISNUMBER(F24)))"),0.0) -> 0
A25: INVESTMENT ACTIVITY OF NATURAL MONOPOLIES OF SARATOV REGION: PROBLEMS AND SOLUTIONS | B25: https://doi.org/10.15405/epsbs.2019.03.02.216 | C25: Russian Foundation for Basic Research; RFBR; РФФИ; Российский Фонд Фундаментальных Исследований || NOT MATCHED | D25: https://openalex.org/funders/f4320321079 | E25: =sample_20250925!E25 -> 2 | F25: 1 | G25: 0 | H25: Jacob | M25: =F25/E25 -> 0.5 | N25: =G25/E25 -> 0 | O25: =IFERROR(__xludf.DUMMYFUNCTION("INT(FILTER(GT(F25,0),ISNUMBER(F25)))"),1.0) -> 1 | P25: =F25/(F25+G25) -> 1 | Q25: =IFERROR(__xludf.DUMMYFUNCTION("INT(FILTER(EQ(E25,F25),ISNUMBER(E25),ISNUMBER(F25)))"),0.0) -> 0
A26: Mathematical Modelling and Electrical Analog Equivalent of the Human Cardiovascular System | B26: https://doi.org/10.1007/s10558-010-9093-0 | C26: Iran University of Science and Technology; Iran University of Science & Technology; IUST || NOT MATCHED | D26: https://openalex.org/funders/f4320324096 | E26: =sample_20250925!E26 -> 2 | F26: 1 | G26: 0 | H26: Jacob | M26: =F26/E26 -> 0.5 | N26: =G26/E26 -> 0 | O26: =IFERROR(__xludf.DUMMYFUNCTION("INT(FILTER(GT(F26,0),ISNUMBER(F26)))"),1.0) -> 1 | P26: =F26/(F26+G26) -> 1 | Q26: =IFERROR(__xludf.DUMMYFUNCTION("INT(FILTER(EQ(E26,F26),ISNUMBER(E26),ISNUMBER(F26)))"),0.0) -> 0
A27: Characterizing Serpinb2 as a Modulator of TCDD-Induced Suppression of the B Cell | B27: https://doi.org/10.1021/acs.chemrestox.8b00225 | C27: National Institute of Environmental Health Sciences; The National Institute of Environmental Health Sciences; NIH National Institute of Environmental Health Sciences; NIEHS || Michigan State University; Michigan State University Spartans; MSU || National Institute of Environmental Health Sciences; The National Institute of Environmental Health Sciences; NIH National Institute of Environmental Health Sciences; NIEHS || National Institute of Environmental Health Sciences; The National Institute of Environmental Health Sciences; NIH National Institute of Environmental Health Sciences; NIEHS | D27: https://openalex.org/funders/f4320337361 || https://openalex.org/funders/f4320310016 | E27: =sample_20250925!E27 -> 2 | F27: =IF(sample_20250925!$C27=C27,sample_20250925!F27, NA()) -> 1 | G27: =IF(sample_20250925!$C27=$C27,sample_20250925!G27, NA()) -> 0 | H27: Jacob | M27: =F27/E27 -> 0.5 | N27: =G27/E27 -> 0 | O27: =IFERROR(__xludf.DUMMYFUNCTION("INT(FILTER(GT(F27,0),ISNUMBER(F27)))"),1.0) -> 1 | P27: =F27/(F27+G27) -> 1 | Q27: =IFERROR(__xludf.DUMMYFUNCTION("INT(FILTER(EQ(E27,F27),ISNUMBER(E27),ISNUMBER(F27)))"),0.0) -> 0
A28: Targeting vulnerable households in urban Burkina Faso: effectiveness of geographical criteria but not of proxy-means testing | B28: https://doi.org/10.1093/heapol/czv104 | C28: World Food Programme; WFP; Programa Mundial de Alimentos; Programma Alimentare Mondiale; Programme Alimentaire Mondial || Institut de Recherche pour le Développement; IRD; Institute for development research IRD; French Research Institute for Development; Instituto de Investigación por el Desarrollo; Institute for development research; French National Research Institute for Sustainable Development | D28: https://openalex.org/institutions/i1295768896 || https://openalex.org/funders/f4320313932 | E28: =sample_20250925!E28 -> 2 | F28: 2 | G28: 0 | H28: Jacob | M28: =F28/E28 -> 1 | N28: =G28/E28 -> 0 | O28: =IFERROR(__xludf.DUMMYFUNCTION("INT(FILTER(GT(F28,0),ISNUMBER(F28)))"),1.0) -> 1 | P28: =F28/(F28+G28) -> 1 | Q28: =IFERROR(__xludf.DUMMYFUNCTION("INT(FILTER(EQ(E28,F28),ISNUMBER(E28),ISNUMBER(F28)))"),1.0) -> 1
A29: Onset of remission and relapse in depression: Testing operational criteria through course description in a second Dublin cohort of first-admission participants | B29: https://doi.org/10.1016/j.jad.2010.02.107 | C29: St. Patrick's Hospital; St. Patrick's University Hospital || Trinity College, University of Oxford; Trinity College | D29: https://openalex.org/funders/f4320334671 || https://openalex.org/institutions/i4210122413 | E29: =sample_20250925!E29 -> 2 | F29: =IF(sample_20250925!$C29=C29,sample_20250925!F29, NA()) -> 2 | G29: =IF(sample_20250925!$C29=$C29,sample_20250925!G29, NA()) -> 0 | H29: Jacob | M29: =F29/E29 -> 1 | N29: =G29/E29 -> 0 | O29: =IFERROR(__xludf.DUMMYFUNCTION("INT(FILTER(GT(F29,0),ISNUMBER(F29)))"),1.0) -> 1 | P29: =F29/(F29+G29) -> 1 | Q29: =IFERROR(__xludf.DUMMYFUNCTION("INT(FILTER(EQ(E29,F29),ISNUMBER(E29),ISNUMBER(F29)))"),1.0) -> 1
A30: Preparative isolation and purification of capsaicinoids from Capsicum frutescens using high-speed counter-current chromatography | B30: https://doi.org/10.1016/j.seppur.2008.10.005 | C30: National Natural Science Foundation of China; NNSF of China; Guójiā Zìrán Kēxué Jījīn Wěiyuánhuì; NSF of China; The National Natural Science Foundation of China; 国家自然科学基金委员会; National Nature Science Foundation of China; NSFC; National Science Foundation of China; Natural Science Foundation of China; NNSFC; Chinese National Science Foundation; NNSF || NOT MATCHED | D30: https://openalex.org/funders/f4320321001 | E30: =sample_20250925!E30 -> 2 | F30: 1 | G30: 0 | H30: Jacob | M30: =F30/E30 -> 0.5 | N30: =G30/E30 -> 0 | O30: =IFERROR(__xludf.DUMMYFUNCTION("INT(FILTER(GT(F30,0),ISNUMBER(F30)))"),1.0) -> 1 | P30: =F30/(F30+G30) -> 1 | Q30: =IFERROR(__xludf.DUMMYFUNCTION("INT(FILTER(EQ(E30,F30),ISNUMBER(E30),ISNUMBER(F30)))"),0.0) -> 0
A31: Clinical and ultrasonographic differences between cattle and buffaloes with various sequelae of traumatic reticuloperitonitis | B31: https://doi.org/10.17221/128/2009-VETMED | C31: Ministry of Higher Education; Ministry of Higher Education, Egypt; MOHE; Egyptian Ministry of Higher Education | D31: https://openalex.org/funders/f4320321147 | E31: =sample_20250925!E31 -> 1 | F31: =IF(sample_20250925!$C31=C31,sample_20250925!F31, NA()) -> 1 | G31: =IF(sample_20250925!$C31=$C31,sample_20250925!G31, NA()) -> 0 | H31: Jacob | M31: =F31/E31 -> 1 | N31: =G31/E31 -> 0 | O31: =IFERROR(__xludf.DUMMYFUNCTION("INT(FILTER(GT(F31,0),ISNUMBER(F31)))"),1.0) -> 1 | P31: =F31/(F31+G31) -> 1 | Q31: =IFERROR(__xludf.DUMMYFUNCTION("INT(FILTER(EQ(E31,F31),ISNUMBER(E31),ISNUMBER(F31)))"),1.0) -> 1
A32: Influence of grain type and oil concentration of dried corn distillers' grain with solubles on ruminal fermentation and in vitro gas production in cattle fed high-concentrate diets | B32: https://doi.org/10.1139/cjas-2018-0036 | C32: North Dakota Corn Utilization Council; North Dakota Corn; NDCUC; North Dakota Corn Council; ND Corn Council | D32: https://openalex.org/funders/f4320318963 | E32: =sample_20250925!E32 -> 1 | F32: =IF(sample_20250925!$C32=C32,sample_20250925!F32, NA()) -> 1 | G32: =IF(sample_20250925!$C32=$C32,sample_20250925!G32, NA()) -> 0 | H32: Jacob | M32: =F32/E32 -> 1 | N32: =G32/E32 -> 0 | O32: =IFERROR(__xludf.DUMMYFUNCTION("INT(FILTER(GT(F32,0),ISNUMBER(F32)))"),1.0) -> 1 | P32: =F32/(F32+G32) -> 1 | Q32: =IFERROR(__xludf.DUMMYFUNCTION("INT(FILTER(EQ(E32,F32),ISNUMBER(E32),ISNUMBER(F32)))"),1.0) -> 1
A33: IIx myosin heavy chain promoter regulation cannot be characterized in vivo by direct gene transfer | B33: https://doi.org/10.1152/ajpcell.00221.2007 | C33: National Institute of Arthritis and Musculoskeletal and Skin Diseases; NIAMS; Instituto Nacional de Artritis y Enfermedades Musculoesqueléticas y de la Piel; NIH\/National Institute of Arthritis and Musculoskeletal and Skin Diseases; National Institute of Arthritis & Musculoskeletal & Skin Diseases; The National Institute of Arthritis and Musculoskeletal and Skin Diseases; NIH National Institute of Arthritis and Musculoskeletal and Skin Diseases || National Institute of Arthritis and Musculoskeletal and Skin Diseases; NIAMS; Instituto Nacional de Artritis y Enfermedades Musculoesqueléticas y de la Piel; NIH\/National Institute of Arthritis and Musculoskeletal and Skin Diseases; National Institute of Arthritis & Musculoskeletal & Skin Diseases; The National Institute of Arthritis and Musculoskeletal and Skin Diseases; NIH National Institute of Arthritis and Musculoskeletal and Skin Diseases | D33: https://openalex.org/funders/f4320337362 | E33: =sample_20250925!E33 -> 1 | F33: =IF(sample_20250925!$C33=C33,sample_20250925!F33, NA()) -> 1 | G33: =IF(sample_20250925!$C33=$C33,sample_20250925!G33, NA()) -> 0 | H33: Jacob | M33: =F33/E33 -> 1 | N33: =G33/E33 -> 0 | O33: =IFERROR(__xludf.DUMMYFUNCTION("INT(FILTER(GT(F33,0),ISNUMBER(F33)))"),1.0) -> 1 | P33: =F33/(F33+G33) -> 1
A34: Crash responses under multiple impacts and residual properties of CFRP and aluminum tubes | B34: https://doi.org/10.1016/j.compstruct.2018.04.001 | C34: National Natural Science Foundation of China; NNSF of China; Guójiā Zìrán Kēxué Jījīn Wěiyuánhuì; NSF of China; The National Natural Science Foundation of China; 国家自然科学基金委员会; National Nature Science Foundation of China; NSFC; National Science Foundation of China; Natural Science Foundation of China; NNSFC; Chinese National Science Foundation; NNSF || NOT MATCHED || Natural Science Foundation of Guangdong Province; Guangdong Natural Science Foundation; Guangdong Provincial Natural Science Foundation; Natural Science Foundation of Guangdong || Natural Science Foundation of Hunan Province; Hunan Provincial Natural Science Foundation || China Postdoctoral Science Foundation || NOT MATCHED | D34: https://openalex.org/funders/f4320322843 || https://openalex.org/funders/f4320321921 || https://openalex.org/funders/f4320321001 || https://openalex.org/funders/f4320321543 | E34: =sample_20250925!E34 -> 6 | F34: 4 | G34: 0 | H34: Jacob | M34: =F34/E34 -> 0.66666667 | N34: =G34/E34 -> 0 | O34: =IFERROR(__xludf.DUMMYFUNCTION("INT(FILTER(GT(F34,0),ISNUMBER(F34)))"),1.0) -> 1 | P34: =F34/(F34+G34) -> 1 | Q34: =IFERROR(__xludf.DUMMYFUNCTION("INT(FILTER(EQ(E34,F34),ISNUMBER(E34),ISNUMBER(F34)))"),0.0) -> 0
A35: Inactivation of a pathogenic NDM-1-positive Escherichia coli strain and the resistance gene bla(NDM-1) by TiO2/UVA photocatalysis | B35: https://doi.org/10.1016/j.scitotenv.2022.157369 | C35: Government of Jiangsu Province; Jiangsu Province || NOT MATCHED || National Natural Science Foundation of China; NNSF of China; Guójiā Zìrán Kēxué Jījīn Wěiyuánhuì; NSF of China; The National Natural Science Foundation of China; 国家自然科学基金委员会; National Nature Science Foundation of China; NSFC; National Science Foundation of China; Natural Science Foundation of China; NNSFC; Chinese National Science Foundation; NNSF | D35: https://openalex.org/funders/f4320321001 || https://openalex.org/funders/f4320321605 | E35: =sample_20250925!E35 -> 3 | F35: 2 | G35: 0 | H35: Jacob | M35: =F35/E35 -> 0.66666667 | N35: =G35/E35 -> 0 | O35: =IFERROR(__xludf.DUMMYFUNCTION("INT(FILTER(GT(F35,0),ISNUMBER(F35)))"),1.0) -> 1 | P35: =F35/(F35+G35) -> 1 | Q35: =IFERROR(__xludf.DUMMYFUNCTION("INT(FILTER(EQ(E35,F35),ISNUMBER(E35),ISNUMBER(F35)))"),0.0) -> 0
A36: Comparison of phase-shifting techniques for in vivo full-range, high-speed Fourier-domain optical coherence tomography | B36: https://doi.org/10.1117/1.3494556 | C36: National Eye Institute; NIH\/National Eye Institute; The National Eye Institute; NEI; Instituto Nacional del Ojo || Research to Prevent Blindness; Research to Prevent Blindness, Inc; Research To Prevent Blindness, Inc.; RESEARCH TO PREVENT BLINDNESS INC; RPB || National Eye Institute; NIH\/National Eye Institute; The National Eye Institute; NEI; Instituto Nacional del Ojo | D36: https://openalex.org/funders/f4320337350 || https://openalex.org/funders/f4320306811 | E36: =sample_20250925!E36 -> 2 | F36: =IF(sample_20250925!$C36=C36,sample_20250925!F36, NA()) -> 2 | G36: =IF(sample_20250925!$C36=$C36,sample_20250925!G36, NA()) -> 0 | H36: Jacob | M36: =F36/E36 -> 1 | N36: =G36/E36 -> 0 | O36: =IFERROR(__xludf.DUMMYFUNCTION("INT(FILTER(GT(F36,0),ISNUMBER(F36)))"),1.0) -> 1 | P36: =F36/(F36+G36) -> 1 | Q36: =IFERROR(__xludf.DUMMYFUNCTION("INT(FILTER(EQ(E36,F36),ISNUMBER(E36),ISNUMBER(F36)))"),1.0) -> 1
A37: Experience and Outcome of Children with Severe Acute Malnutrition Using Locally Prepared Therapeutic Diet | B37: https://doi.org/10.1007/s12098-015-1818-z | C37: UNICEF; United Nations Children's Emergency Fund | D37: https://openalex.org/funders/f4320309209 | E37: =sample_20250925!E37 -> 1 | F37: =IF(sample_20250925!$C37=C37,sample_20250925!F37, NA()) -> 1 | G37: =IF(sample_20250925!$C37=$C37,sample_20250925!G37, NA()) -> 0 | H37: Jacob | M37: =F37/E37 -> 1 | N37: =G37/E37 -> 0 | O37: =IFERROR(__xludf.DUMMYFUNCTION("INT(FILTER(GT(F37,0),ISNUMBER(F37)))"),1.0) -> 1 | P37: =F37/(F37+G37) -> 1 | Q37: =IFERROR(__xludf.DUMMYFUNCTION("INT(FILTER(EQ(E37,F37),ISNUMBER(E37),ISNUMBER(F37)))"),1.0) -> 1
A38: Analysis of EV Charging Coordination Efficiency in Presence of Cheating Customers | B38: https://doi.org/10.1109/ACCESS.2021.3128399 | C38: Qatar National Library; QNL; مكتبة قطر الوطنية; Qatar National Library, Doha, Qatar || NOT MATCHED | D38: https://openalex.org/funders/f4320334468 | E38: =sample_20250925!E38 -> 2 | F38: 1 | G38: 0 | H38: Jacob | M38: =F38/E38 -> 0.5 | N38: =G38/E38 -> 0 | O38: =IFERROR(__xludf.DUMMYFUNCTION("INT(FILTER(GT(F38,0),ISNUMBER(F38)))"),1.0) -> 1 | P38: =F38/(F38+G38) -> 1 | Q38: =IFERROR(__xludf.DUMMYFUNCTION("INT(FILTER(EQ(E38,F38),ISNUMBER(E38),ISNUMBER(F38)))"),0.0) -> 0
A39: Inhibitory Effects of Garcinia cambogia Extract on CYP2B6 Enzyme Activity | B39: https://doi.org/10.1055/s-0043-104934 | C39: National Research Foundation of Korea; NRF; 한국연구재단이 창의적 연구와 | D39: https://openalex.org/funders/f4320322120 | E39: 2 | F39: =IF(sample_20250925!$C39=C39,sample_20250925!F39, NA()) -> 1 | G39: =IF(sample_20250925!$C39=$C39,sample_20250925!G39, NA()) -> 0 | H39: Jacob | M39: =F39/E39 -> 0.5 | N39: =G39/E39 -> 0 | O39: =IFERROR(__xludf.DUMMYFUNCTION("INT(FILTER(GT(F39,0),ISNUMBER(F39)))"),1.0) -> 1 | P39: =F39/(F39+G39) -> 1 | Q39: =IFERROR(__xludf.DUMMYFUNCTION("INT(FILTER(EQ(E39,F39),ISNUMBER(E39),ISNUMBER(F39)))"),0.0) -> 0
A40: Preparation of platinum- and silver-incorporated TiO2 coatings in thin-film photoreactor for the photocatalytic decomposition of o-cresol | B40: https://doi.org/10.1080/09593330.2011.556670 | C40: Ministry of Science and Technology, Taiwan; Ministry of Science and Technology of Taiwan; MOST; Ministry of Science and Technology, R.O.C. (Taiwan) | D40: https://openalex.org/funders/f4320322795 | E40: =sample_20250925!E40 -> 1 | F40: 1 | G40: 0 | H40: Jacob | M40: =F40/E40 -> 1 | N40: =G40/E40 -> 0 | O40: =IFERROR(__xludf.DUMMYFUNCTION("INT(FILTER(GT(F40,0),ISNUMBER(F40)))"),1.0) -> 1 | P40: =F40/(F40+G40) -> 1 | Q40: =IFERROR(__xludf.DUMMYFUNCTION("INT(FILTER(EQ(E40,F40),ISNUMBER(E40),ISNUMBER(F40)))"),1.0) -> 1
...

Sheet Openalex
A1: title | B1: DOI | C1: funder_display_name | D1: Number of Funders Indicated by Paper | E1: Number of Correct Matches | F1: Number of Wrong Matches | G1: Coder | H1: Avg. Recall | I1: Avg error rate | J1: Hit rate | K1: Avg. Precision | L1: Paper level recall | M1: Paper level error rate | N1: Paper level hit rate | O1: Paper level precision | P1: Paper is complete hit
A2: Integral-Type Fractional Equations with a Proportional Riemann-Liouville Derivative | B2: https://doi.org/10.1155/2021/9990439 | C2: Prince Sultan University | D2: =VLOOKUP(A2,'Web_of_Science_20251015 '!A:E,5,0) -> 1 | E2: 1 | F2: 0 | G2: Jacob | H2: =IFERROR(__xludf.DUMMYFUNCTION("AVERAGE(FILTER(L2:L101,ISNUMBER(L2:L101)))"),0.6838099415204678) -> 0.68380994 | I2: =IFERROR(__xludf.DUMMYFUNCTION("AVERAGE(FILTER(M2:M101,ISNUMBER(M2:M101)))"),0.050277777777777775) -> 0.050277778 | J2: =IFERROR(__xludf.DUMMYFUNCTION("AVERAGE(FILTER(N2:N101,ISNUMBER(N2:N101)))"),0.95) -> 0.95 | K2: =IFERROR(__xludf.DUMMYFUNCTION("AVERAGE(FILTER(O2:O101,ISNUMBER(O2:O101)))"),0.9358333333333333) -> 0.93583333 | L2: =E2/D2 -> 1 | M2: =F2/D2 -> 0 | N2: =IFERROR(__xludf.DUMMYFUNCTION("INT(FILTER(GT(E2,0),ISNUMBER(E2)))"),1.0) -> 1 | O2: =E2/(E2+F2) -> 1 | P2: =IFERROR(__xludf.DUMMYFUNCTION("INT(FILTER(EQ(D2,E2),ISNUMBER(D2),ISNUMBER(E2)))"),1.0) -> 1
A3: Enzymatic Hydrolysis of Softwood Derived Paper Sludge by an In Vitro Recombinant Cellulase Cocktail for the Production of Fermentable Sugars | B3: https://doi.org/10.3390/catal10070775 | C3: Universiteit Stellenbosch;National Agricultural Research Foundation;Rhodes University | D3: =VLOOKUP(A3,'Web_of_Science_20251015 '!A:E,5,0) -> 4 | E3: 2 | F3: 1 | G3: Jacob | H3: Recall | I3: Error rate | J3: Complete hits | K3: Precision | L3: =E3/D3 -> 0.5 | M3: =F3/D3 -> 0.25 | N3: =IFERROR(__xludf.DUMMYFUNCTION("INT(FILTER(GT(E3,0),ISNUMBER(E3)))"),1.0) -> 1 | O3: =E3/(E3+F3) -> 0.66666667 | P3: =IFERROR(__xludf.DUMMYFUNCTION("INT(FILTER(EQ(D3,E3),ISNUMBER(D3),ISNUMBER(E3)))"),0.0) -> 0
A4: Synthesis of 2-Vinylbenzofurans via the Copper-Catalyzed Multicomponent Reactions Involving an Oxa-Michael/Arylation/Vinylation Cascade | B4: https://doi.org/10.1021/ol502506g | C4: Education Department of Jiangxi Province;National Natural Science Foundation of China | D4: =VLOOKUP(A4,'Web_of_Science_20251015 '!A:E,5,0) -> 2 | E4: 2 | F4: 0 | G4: Jacob | H4: =IFERROR(__xludf.DUMMYFUNCTION("SUM(FILTER(E2:E101,ISNUMBER(E2:E101)))/SUM(FILTER(D2:D101,ISNUMBER(E2:E101)))"),0.6392857142857142) -> 0.63928571 | I4: =IFERROR(__xludf.DUMMYFUNCTION("SUM(FILTER(F2:F101,ISNUMBER(F2:F101)))/SUM(FILTER(D2:D101,ISNUMBER(F2:F101)))"),0.03571428571428571) -> 0.035714286 | J4: =IFERROR(__xludf.DUMMYFUNCTION("AVERAGE(FILTER(P2:P101,ISNUMBER(P2:P101)))"),0.4175824175824176) -> 0.41758242 | K4: =IFERROR(__xludf.DUMMYFUNCTION("SUM(FILTER(E2:E101,ISNUMBER(E2:E101)))/(SUM(FILTER(E2:E101,ISNUMBER(E2:E101)))+SUM(FILTER(F2:F101,ISNUMBER(E2:E101))))"),0.9470899470899471) -> 0.94708995 | L4: =E4/D4 -> 1 | M4: =F4/D4 -> 0 | N4: =IFERROR(__xludf.DUMMYFUNCTION("INT(FILTER(GT(E4,0),ISNUMBER(E4)))"),1.0) -> 1 | O4: =E4/(E4+F4) -> 1 | P4: =IFERROR(__xludf.DUMMYFUNCTION("INT(FILTER(EQ(D4,E4),ISNUMBER(D4),ISNUMBER(E4)))"),1.0) -> 1
A5: Nrf2 augments skeletal muscle regeneration after ischaemia-reperfusion injury | B5: https://doi.org/10.1002/path.4418 | C5: Deutsche Forschungsgemeinschaft | D5: =VLOOKUP(A5,'Web_of_Science_20251015 '!A:E,5,0) -> 3 | E5: 1 | F5: 0 | G5: Jacob | L5: =E5/D5 -> 0.33333333 | M5: =F5/D5 -> 0 | N5: =IFERROR(__xludf.DUMMYFUNCTION("INT(FILTER(GT(E5,0),ISNUMBER(E5)))"),1.0) -> 1 | O5: =E5/(E5+F5) -> 1 | P5: =IFERROR(__xludf.DUMMYFUNCTION("INT(FILTER(EQ(D5,E5),ISNUMBER(D5),ISNUMBER(E5)))"),0.0) -> 0
A6: Crash responses under multiple impacts and residual properties of CFRP and aluminum tubes | B6: https://doi.org/10.1016/j.compstruct.2018.04.001 | C6: China Postdoctoral Science Foundation;National Natural Science Foundation of China;Natural Science Foundation of Guangdong Province;Natural Science Foundation of Hainan Province | D6: =VLOOKUP(A6,'Web_of_Science_20251015 '!A:E,5,0) -> 6 | E6: 3 | F6: 1 | G6: Jacob | L6: =E6/D6 -> 0.5 | M6: =F6/D6 -> 0.16666667 | N6: =IFERROR(__xludf.DUMMYFUNCTION("INT(FILTER(GT(E6,0),ISNUMBER(E6)))"),1.0) -> 1 | O6: =E6/(E6+F6) -> 0.75 | P6: =IFERROR(__xludf.DUMMYFUNCTION("INT(FILTER(EQ(D6,E6),ISNUMBER(D6),ISNUMBER(E6)))"),0.0) -> 0
A7: Inactivation of a pathogenic NDM-1-positive Escherichia coli strain and the resistance gene bla(NDM-1) by TiO2/UVA photocatalysis | B7: https://doi.org/10.1016/j.scitotenv.2022.157369 | C7: National Natural Science Foundation of China;Xuzhou Science and Technology Bureau;Jiangsu Provincial Department of Education | D7: =VLOOKUP(A7,'Web_of_Science_20251015 '!A:E,5,0) -> 3 | E7: 3 | F7: 0 | G7: Jacob | L7: =E7/D7 -> 1 | M7: =F7/D7 -> 0 | N7: =IFERROR(__xludf.DUMMYFUNCTION("INT(FILTER(GT(E7,0),ISNUMBER(E7)))"),1.0) -> 1 | O7: =E7/(E7+F7) -> 1 | P7: =IFERROR(__xludf.DUMMYFUNCTION("INT(FILTER(EQ(D7,E7),ISNUMBER(D7),ISNUMBER(E7)))"),1.0) -> 1
A8: Nitrogen Dioxide Sensing Using Multilayer Structure of Reduced Graphene Oxide and alpha-Fe2O3 | B8: https://doi.org/10.3390/s21031011 | C8: Narodowe Centrum Nauki | D8: =VLOOKUP(A8,'Web_of_Science_20251015 '!A:E,5,0) -> 1 | E8: 1 | F8: 0 | G8: Jacob | L8: =E8/D8 -> 1 | M8: =F8/D8 -> 0 | N8: =IFERROR(__xludf.DUMMYFUNCTION("INT(FILTER(GT(E8,0),ISNUMBER(E8)))"),1.0) -> 1 | O8: =E8/(E8+F8) -> 1 | P8: =IFERROR(__xludf.DUMMYFUNCTION("INT(FILTER(EQ(D8,E8),ISNUMBER(D8),ISNUMBER(E8)))"),1.0) -> 1
A9: A novel lateral shearing interferometer and its anti-vibration characteristic for on-machine precision surface measurement | B9: https://doi.org/10.1016/j.ijleo.2016.03.064 | C9: National Natural Science Foundation of China | D9: =VLOOKUP(A9,'Web_of_Science_20251015 '!A:E,5,0) -> 3 | E9: 1 | F9: 0 | G9: Jacob | L9: =E9/D9 -> 0.33333333 | M9: =F9/D9 -> 0 | N9: =IFERROR(__xludf.DUMMYFUNCTION("INT(FILTER(GT(E9,0),ISNUMBER(E9)))"),1.0) -> 1 | O9: =E9/(E9+F9) -> 1 | P9: =IFERROR(__xludf.DUMMYFUNCTION("INT(FILTER(EQ(D9,E9),ISNUMBER(D9),ISNUMBER(E9)))"),0.0) -> 0
A10: On the Non-trivial Origin of Atomic-Scale Patterns in Friction Force Microscopy | B10: https://doi.org/10.1007/s11249-018-1127-6 | C10: European Research Council;Foundation for Fundamental Research on Matter | D10: =VLOOKUP(A10,'Web_of_Science_20251015 '!A:E,5,0) -> 2 | E10: 2 | F10: 0 | G10: Jacob | L10: =E10/D10 -> 1 | M10: =F10/D10 -> 0 | N10: =IFERROR(__xludf.DUMMYFUNCTION("INT(FILTER(GT(E10,0),ISNUMBER(E10)))"),1.0) -> 1 | O10: =E10/(E10+F10) -> 1 | P10: =IFERROR(__xludf.DUMMYFUNCTION("INT(FILTER(EQ(D10,E10),ISNUMBER(D10),ISNUMBER(E10)))"),1.0) -> 1
A11: Professional identity research in the health professions-a scoping review | B11: https://doi.org/10.1007/s10459-022-10171-1 | C11: Monash University | D11: =VLOOKUP(A11,'Web_of_Science_20251015 '!A:E,5,0) -> 2 | E11: 0 | F11: 1 | G11: Jacob | L11: =E11/D11 -> 0 | M11: =F11/D11 -> 0.5 | N11: =IFERROR(__xludf.DUMMYFUNCTION("INT(FILTER(GT(E11,0),ISNUMBER(E11)))"),0.0) -> 0 | O11: =E11/(E11+F11) -> 0
A12: Parental Life Span and Polygenic Risk Score of Longevity Are Associated With White Matter Hyperintensities | B12: https://doi.org/10.1093/gerona/glab323 | C12: National Health and Medical Research Council | D12: =VLOOKUP(A12,'Web_of_Science_20251015 '!A:E,5,0) -> 2 | E12: 1 | F12: 0 | G12: Jacob | L12: =E12/D12 -> 0.5 | M12: =F12/D12 -> 0 | N12: =IFERROR(__xludf.DUMMYFUNCTION("INT(FILTER(GT(E12,0),ISNUMBER(E12)))"),1.0) -> 1 | O12: =E12/(E12+F12) -> 1 | P12: =IFERROR(__xludf.DUMMYFUNCTION("INT(FILTER(EQ(D12,E12),ISNUMBER(D12),ISNUMBER(E12)))"),0.0) -> 0
A13: Developing Concentration Index of Industrial and Occupational Accidents: The Case of European Countries | B13: https://doi.org/10.1016/j.shaw.2020.05.003 | C13: National Research Foundation of Korea | D13: =VLOOKUP(A13,'Web_of_Science_20251015 '!A:E,5,0) -> 2 | E13: 1 | F13: 0 | G13: Jacob | L13: =E13/D13 -> 0.5 | M13: =F13/D13 -> 0 | N13: =IFERROR(__xludf.DUMMYFUNCTION("INT(FILTER(GT(E13,0),ISNUMBER(E13)))"),1.0) -> 1 | O13: =E13/(E13+F13) -> 1 | P13: =IFERROR(__xludf.DUMMYFUNCTION("INT(FILTER(EQ(D13,E13),ISNUMBER(D13),ISNUMBER(E13)))"),0.0) -> 0
A14: Analysis of the Fee-to-Tax Reform on Water Resources in China | B14: https://doi.org/10.3389/fenrg.2021.752592 | C14: Guangdong Office of Philosophy and Social Science | D14: =VLOOKUP(A14,'Web_of_Science_20251015 '!A:E,5,0) -> 1 | E14: 1 | F14: 0 | G14: Jacob | L14: =E14/D14 -> 1 | M14: =F14/D14 -> 0 | N14: =IFERROR(__xludf.DUMMYFUNCTION("INT(FILTER(GT(E14,0),ISNUMBER(E14)))"),1.0) -> 1 | O14: =E14/(E14+F14) -> 1 | P14: =IFERROR(__xludf.DUMMYFUNCTION("INT(FILTER(EQ(D14,E14),ISNUMBER(D14),ISNUMBER(E14)))"),1.0) -> 1
A15: Bifurcation Phenomena of Nonlinear Waves in a Generalized Zakharov-Kuznetsov Equation | B15: https://doi.org/10.1155/2013/812120 | C15: National Natural Science Foundation of China | D15: =VLOOKUP(A15,'Web_of_Science_20251015 '!A:E,5,0) -> 2 | E15: 1 | F15: 0 | G15: Jacob | L15: =E15/D15 -> 0.5 | M15: =F15/D15 -> 0 | N15: =IFERROR(__xludf.DUMMYFUNCTION("INT(FILTER(GT(E15,0),ISNUMBER(E15)))"),1.0) -> 1 | O15: =E15/(E15+F15) -> 1 | P15: =IFERROR(__xludf.DUMMYFUNCTION("INT(FILTER(EQ(D15,E15),ISNUMBER(D15),ISNUMBER(E15)))"),0.0) -> 0
A16: Gall size of Dryocosmus kuriphilus limits down-regulation by native parasitoids | B16: https://doi.org/10.1007/s10530-020-02427-x | C16: Ministerio de Asuntos Económicos y Transformación Digital, Gobierno de España | D16: =VLOOKUP(A16,'Web_of_Science_20251015 '!A:E,5,0) -> 1 | E16: 1 | F16: 0 | G16: Jacob | L16: =E16/D16 -> 1 | M16: =F16/D16 -> 0 | N16: =IFERROR(__xludf.DUMMYFUNCTION("INT(FILTER(GT(E16,0),ISNUMBER(E16)))"),1.0) -> 1 | O16: =E16/(E16+F16) -> 1 | P16: =IFERROR(__xludf.DUMMYFUNCTION("INT(FILTER(EQ(D16,E16),ISNUMBER(D16),ISNUMBER(E16)))"),1.0) -> 1
A17: Dynamic Characteristics Analysis of ISD Suspension System under Different Working Conditions | B17: https://doi.org/10.3390/math9121345 | C17: National Natural Science Foundation of China | D17: =VLOOKUP(A17,'Web_of_Science_20251015 '!A:E,5,0) -> 2 | E17: 1 | F17: 0 | G17: Jacob | L17: =E17/D17 -> 0.5 | M17: =F17/D17 -> 0 | N17: =IFERROR(__xludf.DUMMYFUNCTION("INT(FILTER(GT(E17,0),ISNUMBER(E17)))"),1.0) -> 1 | O17: =E17/(E17+F17) -> 1 | P17: =IFERROR(__xludf.DUMMYFUNCTION("INT(FILTER(EQ(D17,E17),ISNUMBER(D17),ISNUMBER(E17)))"),0.0) -> 0
A18: Dynamic covalent chemistry constrained diphenylethenes: control over reactivity and luminescence both in solution and in the solid state | B18: https://doi.org/10.1039/d2qo00057a | C18: Key Research Program of Frontier Science, Chinese Academy of Sciences;Natural Science Foundation of Fujian Province;National Natural Science Foundation of China | D18: =VLOOKUP(A18,'Web_of_Science_20251015 '!A:E,5,0) -> 5 | E18: 3 | F18: 0 | G18: Jacob | L18: =E18/D18 -> 0.6 | M18: =F18/D18 -> 0 | N18: =IFERROR(__xludf.DUMMYFUNCTION("INT(FILTER(GT(E18,0),ISNUMBER(E18)))"),1.0) -> 1 | O18: =E18/(E18+F18) -> 1 | P18: =IFERROR(__xludf.DUMMYFUNCTION("INT(FILTER(EQ(D18,E18),ISNUMBER(D18),ISNUMBER(E18)))"),0.0) -> 0
A19: Dynamic changes in positive interferon-gamma release assay in a dialysis population: An observational cohort study | B19: https://doi.org/10.1016/j.jinf.2013.07.029 | C19: National Research Program for Biopharmaceuticals | D19: =VLOOKUP(A19,'Web_of_Science_20251015 '!A:E,5,0) -> 3 | E19: 1 | F19: 0 | G19: Jacob | L19: =E19/D19 -> 0.33333333 | M19: =F19/D19 -> 0 | N19: =IFERROR(__xludf.DUMMYFUNCTION("INT(FILTER(GT(E19,0),ISNUMBER(E19)))"),1.0) -> 1 | O19: =E19/(E19+F19) -> 1 | P19: =IFERROR(__xludf.DUMMYFUNCTION("INT(FILTER(EQ(D19,E19),ISNUMBER(D19),ISNUMBER(E19)))"),0.0) -> 0
A20: Molnupiravir-A Novel Oral Anti-SARS-CoV-2 Agent | B20: https://doi.org/10.3390/antibiotics10111294 | C20: Ministry of Health and Welfare;Ministry of Science and Technology, Taiwan;National Cheng Kung University Hospital | D20: =VLOOKUP(A20,'Web_of_Science_20251015 '!A:E,5,0) -> 3 | E20: 3 | F20: 0 | G20: Jacob | L20: =E20/D20 -> 1 | M20: =F20/D20 -> 0 | N20: =IFERROR(__xludf.DUMMYFUNCTION("INT(FILTER(GT(E20,0),ISNUMBER(E20)))"),1.0) -> 1 | O20: =E20/(E20+F20) -> 1 | P20: =IFERROR(__xludf.DUMMYFUNCTION("INT(FILTER(EQ(D20,E20),ISNUMBER(D20),ISNUMBER(E20)))"),1.0) -> 1
A21: Tailoring modulus and hardness of in-situ formed beta-Ti in bulk metallic glass composites by precipitation of isothermal omega-Ti | B21: https://doi.org/10.1016/j.matdes.2017.07.062 | C21: National Natural Science Foundation of China | D21: =VLOOKUP(A21,'Web_of_Science_20251015 '!A:E,5,0) -> 4 | E21: 1 | F21: 0 | G21: Jacob | L21: =E21/D21 -> 0.25 | M21: =F21/D21 -> 0 | N21: =IFERROR(__xludf.DUMMYFUNCTION("INT(FILTER(GT(E21,0),ISNUMBER(E21)))"),1.0) -> 1 | O21: =E21/(E21+F21) -> 1 | P21: =IFERROR(__xludf.DUMMYFUNCTION("INT(FILTER(EQ(D21,E21),ISNUMBER(D21),ISNUMBER(E21)))"),0.0) -> 0
A22: Comparative genomics of extrachromosomal elements in Bacillus thuringiensis subsp israelensis | B22: https://doi.org/10.1016/j.resmic.2016.10.008 | C22: Fonds De La Recherche Scientifique - FNRS;Agence Nationale de la Recherche;Université Catholique de Louvain | D22: =VLOOKUP(A22,'Web_of_Science_20251015 '!A:E,5,0) -> 3 | E22: 3 | F22: 0 | G22: Jacob | L22: =E22/D22 -> 1 | M22: =F22/D22 -> 0 | N22: =IFERROR(__xludf.DUMMYFUNCTION("INT(FILTER(GT(E22,0),ISNUMBER(E22)))"),1.0) -> 1 | O22: =E22/(E22+F22) -> 1
A23: Bicarbonate-based cultivation of Dunaliella salina for enhancing carbon utilization efficiency | B23: https://doi.org/10.1016/j.biortech.2017.04.009 | C23: Korea Electric Power Corporation | D23: =VLOOKUP(A23,'Web_of_Science_20251015 '!A:E,5,0) -> 2 | E23: 1 | F23: 0 | G23: Jacob | L23: =E23/D23 -> 0.5 | M23: =F23/D23 -> 0 | N23: =IFERROR(__xludf.DUMMYFUNCTION("INT(FILTER(GT(E23,0),ISNUMBER(E23)))"),1.0) -> 1 | O23: =E23/(E23+F23) -> 1 | P23: =IFERROR(__xludf.DUMMYFUNCTION("INT(FILTER(EQ(D23,E23),ISNUMBER(D23),ISNUMBER(E23)))"),0.0) -> 0
A24: Polysaccharides from chayote enhance lipid efflux and regulate NLRP3 inflammasome priming in macrophage-like THP-1 cells exposed to cholesterol crystals | B24: https://doi.org/10.1016/j.ijbiomac.2019.01.048 | C24: Coordenação de Aperfeiçoamento de Pessoal de Nível Superior;Fundação de Amparo à Pesquisa do Estado de São Paulo;Conselho Nacional de Desenvolvimento Científico e Tecnológico | D24: =VLOOKUP(A24,'Web_of_Science_20251015 '!A:E,5,0) -> 3 | E24: 3 | F24: 0 | G24: Jacob | L24: =E24/D24 -> 1 | M24: =F24/D24 -> 0 | N24: =IFERROR(__xludf.DUMMYFUNCTION("INT(FILTER(GT(E24,0),ISNUMBER(E24)))"),1.0) -> 1 | O24: =E24/(E24+F24) -> 1 | P24: =IFERROR(__xludf.DUMMYFUNCTION("INT(FILTER(EQ(D24,E24),ISNUMBER(D24),ISNUMBER(E24)))"),1.0) -> 1
A25: Mineral assemblage transformation of a metakaolin-based waste form after geopolymer encapsulation | B25: https://doi.org/10.1016/j.jnucmat.2015.12.023 | C25: Office of Environmental Management;Biological and Environmental Research | D25: =VLOOKUP(A25,'Web_of_Science_20251015 '!A:E,5,0) -> 1 | E25: 1 | F25: 0 | G25: Jacob | L25: =E25/D25 -> 1 | M25: =F25/D25 -> 0 | N25: =IFERROR(__xludf.DUMMYFUNCTION("INT(FILTER(GT(E25,0),ISNUMBER(E25)))"),1.0) -> 1 | O25: =E25/(E25+F25) -> 1 | P25: =IFERROR(__xludf.DUMMYFUNCTION("INT(FILTER(EQ(D25,E25),ISNUMBER(D25),ISNUMBER(E25)))"),1.0) -> 1
A26: Effects of zirconium silicate reinforcement on expandable graphite based intumescent fire retardant coating | B26: https://doi.org/10.1016/j.polymdegradstab.2014.02.016 | C26: Universiti Teknologi Petronas | D26: =VLOOKUP(A26,'Web_of_Science_20251015 '!A:E,5,0) -> 1 | E26: 1 | F26: 0 | G26: Jacob | L26: =E26/D26 -> 1 | M26: =F26/D26 -> 0 | N26: =IFERROR(__xludf.DUMMYFUNCTION("INT(FILTER(GT(E26,0),ISNUMBER(E26)))"),1.0) -> 1 | O26: =E26/(E26+F26) -> 1 | P26: =IFERROR(__xludf.DUMMYFUNCTION("INT(FILTER(EQ(D26,E26),ISNUMBER(D26),ISNUMBER(E26)))"),1.0) -> 1
A27: Energy Landscapes of Dynamic Ensembles of Rolling Triplet Repeat Bulge Loops: Implications for DNA Expansion Associated with Disease States | B27: https://doi.org/10.1021/ja3010896 | C27: National Institutes of Health | D27: =VLOOKUP(A27,'Web_of_Science_20251015 '!A:E,5,0) -> 3 | E27: 1 | F27: 0 | G27: Jacob | L27: =E27/D27 -> 0.33333333 | M27: =F27/D27 -> 0 | N27: =IFERROR(__xludf.DUMMYFUNCTION("INT(FILTER(GT(E27,0),ISNUMBER(E27)))"),1.0) -> 1 | O27: =E27/(E27+F27) -> 1 | P27: =IFERROR(__xludf.DUMMYFUNCTION("INT(FILTER(EQ(D27,E27),ISNUMBER(D27),ISNUMBER(E27)))"),0.0) -> 0
A28: Mechanochemical Synthesis of Ketones via Chemoselective Suzuki-Miyaura Cross-Coupling of Acyl Chlorides | B28: https://doi.org/10.1021/acs.orglett.2c00519 | C28: National Natural Science Foundation of China;Division of Chemistry | D28: =VLOOKUP(A28,'Web_of_Science_20251015 '!A:E,5,0) -> 3 | E28: 2 | F28: 0 | G28: Jacob | L28: =E28/D28 -> 0.66666667 | M28: =F28/D28 -> 0 | N28: =IFERROR(__xludf.DUMMYFUNCTION("INT(FILTER(GT(E28,0),ISNUMBER(E28)))"),1.0) -> 1 | O28: =E28/(E28+F28) -> 1 | P28: =IFERROR(__xludf.DUMMYFUNCTION("INT(FILTER(EQ(D28,E28),ISNUMBER(D28),ISNUMBER(E28)))"),0.0) -> 0
A29: Model reduction: When singular perturbation analysis simplifies to partial equilibrium approximation | B29: https://doi.org/10.1016/j.combustflame.2014.09.022 | C29: European Social Fund;European Commission | D29: =VLOOKUP(A29,'Web_of_Science_20251015 '!A:E,5,0) -> 2 | E29: 1 | F29: 0 | G29: Jacob | L29: =E29/D29 -> 0.5 | M29: =F29/D29 -> 0 | N29: =IFERROR(__xludf.DUMMYFUNCTION("INT(FILTER(GT(E29,0),ISNUMBER(E29)))"),1.0) -> 1 | O29: =E29/(E29+F29) -> 1 | P29: =IFERROR(__xludf.DUMMYFUNCTION("INT(FILTER(EQ(D29,E29),ISNUMBER(D29),ISNUMBER(E29)))"),0.0) -> 0
A30: Proteomics and Phosphoproteomics Profiling of Drug-Addicted BRAFi-Resistant Melanoma Cells | B30: https://doi.org/10.1021/acs.jproteome.1c00331 | C30: China Scholarship Council;Nederlandse Organisatie voor Wetenschappelijk Onderzoek | D30: =VLOOKUP(A30,'Web_of_Science_20251015 '!A:E,5,0) -> 2 | E30: 2 | F30: 0 | G30: Jacob | L30: =E30/D30 -> 1 | M30: =F30/D30 -> 0 | N30: =IFERROR(__xludf.DUMMYFUNCTION("INT(FILTER(GT(E30,0),ISNUMBER(E30)))"),1.0) -> 1 | O30: =E30/(E30+F30) -> 1 | P30: =IFERROR(__xludf.DUMMYFUNCTION("INT(FILTER(EQ(D30,E30),ISNUMBER(D30),ISNUMBER(E30)))"),1.0) -> 1
A31: A multi-class SVM approach based on the l(1)-norm minimization of the distances between the reduced convex hulls | B31: https://doi.org/10.1016/j.patcog.2014.12.006 | C31: Fondo Nacional de Desarrollo Científico y Tecnológico | D31: =VLOOKUP(A31,'Web_of_Science_20251015 '!A:E,5,0) -> 2 | E31: 1 | F31: 0 | G31: Jacob | L31: =E31/D31 -> 0.5 | M31: =F31/D31 -> 0 | N31: =IFERROR(__xludf.DUMMYFUNCTION("INT(FILTER(GT(E31,0),ISNUMBER(E31)))"),1.0) -> 1 | O31: =E31/(E31+F31) -> 1 | P31: =IFERROR(__xludf.DUMMYFUNCTION("INT(FILTER(EQ(D31,E31),ISNUMBER(D31),ISNUMBER(E31)))"),0.0) -> 0
A32: Oxidative Dissolution of Arsenic-Bearing Sulfide Minerals inGroundwater: Impact of Hydrochemical and HydrodynamicConditions on Arsenic Release and Surface Evolution | B32: https://doi.org/10.1021/acs.est.2c00309 | C32: Danmarks Frie Forskningsfond;Villum Fonden | D32: =VLOOKUP(A32,'Web_of_Science_20251015 '!A:E,5,0) -> 2 | E32: 2 | F32: 0 | G32: Jacob | L32: =E32/D32 -> 1 | M32: =F32/D32 -> 0 | N32: =IFERROR(__xludf.DUMMYFUNCTION("INT(FILTER(GT(E32,0),ISNUMBER(E32)))"),1.0) -> 1 | O32: =E32/(E32+F32) -> 1 | P32: =IFERROR(__xludf.DUMMYFUNCTION("INT(FILTER(EQ(D32,E32),ISNUMBER(D32),ISNUMBER(E32)))"),1.0) -> 1
A33: Classification Method and Determination of Mountainous Area Types at Township Scales: A Case Study of Yuxi City, Yunnan Province | B33: https://doi.org/10.1155/2020/3484568 | C33: National Natural Science Foundation of China | D33: =VLOOKUP(A33,'Web_of_Science_20251015 '!A:E,5,0) -> 3 | E33: 1 | F33: 0 | G33: Jacob | L33: =E33/D33 -> 0.33333333 | M33: =F33/D33 -> 0 | N33: =IFERROR(__xludf.DUMMYFUNCTION("INT(FILTER(GT(E33,0),ISNUMBER(E33)))"),1.0) -> 1 | O33: =E33/(E33+F33) -> 1
A34: A new twist for Stork-Danheiser products enabled by visible light mediated trans-cyclohexene formation; access to acyclic distal enones | B34: https://doi.org/10.1039/d1sc03774a | C34: Herman Frasch Foundation for Chemical Research;National Science Foundation;National Institute of General Medical Sciences | D34: =VLOOKUP(A34,'Web_of_Science_20251015 '!A:E,5,0) -> 4 | E34: 3 | F34: 0 | G34: Jacob | L34: =E34/D34 -> 0.75 | M34: =F34/D34 -> 0 | N34: =IFERROR(__xludf.DUMMYFUNCTION("INT(FILTER(GT(E34,0),ISNUMBER(E34)))"),1.0) -> 1 | O34: =E34/(E34+F34) -> 1 | P34: =IFERROR(__xludf.DUMMYFUNCTION("INT(FILTER(EQ(D34,E34),ISNUMBER(D34),ISNUMBER(E34)))"),0.0) -> 0
